Workbook

Sheet Spells List
C1: Click button/link to filter view. Updated May 7th, 2023. Submit Errors & Omissions.
E2: =HYPERLINK("https://docs.google.com/spreadsheets/d/1LNrLMVYyd306jR2KTeo3D2aKOXg3gN7ZjqvpuqQwcfE/edit#gid=0",IMAGE("https://docs.google.com/drawings/d/e/2PACX-1vSWClHE0jSQi8W_5mD2IrBvSKEkkfMPT69j4Ud4x8UxL4f1yPsoBqNRTdzxnNqPXYSQXHzXA1SwLQ_Q/pub?w=678&h=521")) | F2: =HYPERLINK("https://docs.google.com/spreadsheets/d/1LNrLMVYyd306jR2KTeo3D2aKOXg3gN7ZjqvpuqQwcfE/edit#gid=1078251919",IMAGE("https://docs.google.com/drawings/d/e/2PACX-1vSI-rNq8_u7Ei3MBcQcVdkIvFG4mUYg4tFCfq76fmmX-xsW4ZO-wmkMDQ_Vamy0YNENa-aOf4LZEcVZ/pub?w=778&h=599")) | G2: =HYPERLINK("https://docs.google.com/spreadsheets/d/1LNrLMVYyd306jR2KTeo3D2aKOXg3gN7ZjqvpuqQwcfE/edit#gid=208973905",IMAGE("https://docs.google.com/drawings/d/e/2PACX-1vSiJRXVDFJLq7jiqpjBP3Sv1KhAYxN8ga97zqGh7gmWfal60Q4Tx3JxCBOw3tjaArSwiqnvasaZVMTG/pub?w=595&h=458")) | H2: Submit your own homebrewed spells for inclusion! | I2: =HYPERLINK("https://bit.ly/3AUMaH6",IMAGE("https://docs.google.com/drawings/d/e/2PACX-1vTVp531OswDqgLbtAH17IZ8cCok9zrVPFK34jqpyR8JTRafQasvw437G-DgGEmB6SE9vxEhKK7WEhfJ/pub?w=660&h=513"))
A3: Source | B3: Spell Name | C3: Tier # | D3: Spell Type | E3: Duration | F3: Range | G3: Description
A4: CR | B4: Acid Arrow | C4: 2 | D4: Wizard | E4: Focus | F4: Far | G4: You conjure a corrosive bolt that hits one foe, dealing 1d6 damage a round. The bolt remains in the target for as long as you focus.
A5: CR | B5: Alarm | C5: 1 | D5: Wizard | E5: 1 day | F5: Close | G5: Send a strobing orb of energy streaking toward a target within range. Choose an energy type from fire, cold, or electricity. The orb deals 3d8 damage and delivers a concussive blast of the chosen energy type. If the energy type is anathema to the target's existence, the orb deals double damage to it.
A6: CR | B6: Animate Dead | C6: 3 | D6: Wizard | E6: 1 day | F6: Close | G6: You touch one humanoid’s remains, and it rises as a zombie or skeleton under your control. The remains must have at least three limbs and its head intact. The undead creature acts on your turn. After 1 day, the creature collapses into grave dust.
A7: CR | B7: Antimagic Shell | C7: 5 | D7: Wizard | E7: Focus | F7: Self | G7: An invisible, near-sized cube of null-magic appears centered on you. Within the cube, no spells can be cast. Magic items and spells have no effect in the zone, and no magic can enter. The cube moves with you. Spells such as dispel magic have no effect on it. Another antimagic shell does not affect this one.
A8: CR | B8: Arcane Eye | C8: 4 | D8: Wizard | E8: Focus | F8: Near | G8: You conjure an invisible, grape-sized eye within range. You can see through the eye. It can see in the dark out to near range, fly near on your turn, and squeeze through openings as narrow as a keyhole.
A9: CR | B9: Bless | C9: 2 | D9: Priest | E9: Instant | F9: Close | G9: One creature you touch gains a luck token.
A10: CR | B10: Blind/Deafen | C10: 2 | D10: Priest | E10: Focus | F10: Near | G10: You utter a divine censure, blinding or deafening one creature you can see in range. The creature has disadvantage on tasks requiring the lost sense.
A11: CR | B11: Burning Hands | C11: 1 | D11: Wizard | E11: Instant | F11: Close | G11: You spread your fingers with thumbs touching, unleashing a circle of flame that roars out to a close area around where you stand. Creatures within the area of effect take 1d6 damage, and flammable objects catch fire.
A12: CR | B12: Cleansing Weapon | C12: 2 | D12: Priest | E12: 5 rounds | F12: Close | G12: One weapon you touch is wreathed in purifying flames. It deals an additional 1d4 damage (1d6 vs. undead) for the duration.
A13: CR | B13: Cloudkill | C13: 4 | D13: Wizard | E13: 5 rounds | F13: Far | G13: A putrid cloud of yellow poison fills a near-sized cube within range. It spreads around corners. Creatures inside the cloud are blinded and take 2d6 damage at the beginning of their turns. A creature of LV 9 or less that ends its turn fully inside the cloud dies.
A14: CR | B14: Command | C14: 3 | D14: Priest | E14: Focus | F14: Far | G14: You issue a verbal command to one creature in range who can understand you. The command must be one word, such as “kneel.” The target obeys the command for as long as you focus. If your command is ever directly harmful to the creature, it may make a Charisma check vs. your last spellcasting check. On a success, the spell ends.
A15: CR | B15: Commune | C15: 4 | D15: Priest | E15: Instant | F15: Self | G15: You seek your god's counsel. Ask the GM up to three yes or no questions. The GM truthfully answers "yes" or "no" to each. If you cast this spell more than once in 24 hours, treat a failed spellcasting check for it as a critical failure, instead.
... A88: CR | B88: Speak With Dead | C88: 3 | D88: Priest, Wizard | E88: Instant | F88: Close | G88: A dead body you touch answers your questions in a distant, wheezing voice. You can ask the dead body up to three yes or no questions (one at a time). The GM truthfully answers "yes" or "no" to each. If you cast this spell more than once in 24 hours, treat a failed spellcasting check for it as a critical failure, instead.

Sheet Priest
C1: Click button/link to filter view. Updated May 7th, 2023. Submit Errors & Omissions.
E2: =HYPERLINK("https://docs.google.com/spreadsheets/d/1LNrLMVYyd306jR2KTeo3D2aKOXg3gN7ZjqvpuqQwcfE/edit#gid=0",IMAGE("https://docs.google.com/drawings/d/e/2PACX-1vSWClHE0jSQi8W_5mD2IrBvSKEkkfMPT69j4Ud4x8UxL4f1yPsoBqNRTdzxnNqPXYSQXHzXA1SwLQ_Q/pub?w=678&h=521")) | F2: =HYPERLINK("https://docs.google.com/spreadsheets/d/1LNrLMVYyd306jR2KTeo3D2aKOXg3gN7ZjqvpuqQwcfE/edit#gid=1078251919",IMAGE("https://docs.google.com/drawings/d/e/2PACX-1vSI-rNq8_u7Ei3MBcQcVdkIvFG4mUYg4tFCfq76fmmX-xsW4ZO-wmkMDQ_Vamy0YNENa-aOf4LZEcVZ/pub?w=778&h=599")) | G2: =HYPERLINK("https://docs.google.com/spreadsheets/d/1LNrLMVYyd306jR2KTeo3D2aKOXg3gN7ZjqvpuqQwcfE/edit#gid=208973905",IMAGE("https://docs.google.com/drawings/d/e/2PACX-1vSiJRXVDFJLq7jiqpjBP3Sv1KhAYxN8ga97zqGh7gmWfal60Q4Tx3JxCBOw3tjaArSwiqnvasaZVMTG/pub?w=595&h=458")) | H2: Submit your own homebrewed spells for inclusion! | I2: =HYPERLINK("https://bit.ly/3AUMaH6",IMAGE("https://docs.google.com/drawings/d/e/2PACX-1vTVp531OswDqgLbtAH17IZ8cCok9zrVPFK34jqpyR8JTRafQasvw437G-DgGEmB6SE9vxEhKK7WEhfJ/pub?w=660&h=513"))
A3: Source | B3: Spell Name | C3: Tier # | D3: Spell Type | E3: Duration | F3: Range | G3: Description
A4: =IF(ISNUMBER(SEARCH("Priest",'Spells List'!$D19)),'Spells List'!A19,"") -> CR | B4: =IF(ISNUMBER(SEARCH("Priest",'Spells List'!$D19)),'Spells List'!B19,"") -> Cure Wounds | C4: =IF(ISNUMBER(SEARCH("Priest",'Spells List'!$D19)),'Spells List'!C19,"") -> 1 | D4: =IF(ISNUMBER(SEARCH("Priest",'Spells List'!$D19)),'Spells List'!D19,"") -> Priest | E4: =IF(ISNUMBER(SEARCH("Priest",'Spells List'!$D19)),'Spells List'!E19,"") -> Instant | F4: =IF(ISNUMBER(SEARCH("Priest",'Spells List'!$D19)),'Spells List'!F19,"") -> Close | G4: =IF(ISNUMBER(SEARCH("Priest",'Spells List'!$D19)),'Spells List'!G19,"") -> Your touch restores ebbing life. Roll a number of d6s equal to 1 + half your level (rounded down). One target you touch regains that many hit points.
A5: =IF(ISNUMBER(SEARCH("Priest",'Spells List'!$D38)),'Spells List'!A38,"") -> CR | B5: =IF(ISNUMBER(SEARCH("Priest",'Spells List'!$D38)),'Spells List'!B38,"") -> Holy Weapon | C5: =IF(ISNUMBER(SEARCH("Priest",'Spells List'!$D38)),'Spells List'!C38,"") -> 1 | D5: =IF(ISNUMBER(SEARCH("Priest",'Spells List'!$D38)),'Spells List'!D38,"") -> Priest | E5: =IF(ISNUMBER(SEARCH("Priest",'Spells List'!$D38)),'Spells List'!E38,"") -> 5 rounds | F5: =IF(ISNUMBER(SEARCH("Priest",'Spells List'!$D38)),'Spells List'!F38,"") -> Close | G5: =IF(ISNUMBER(SEARCH("Priest",'Spells List'!$D38)),'Spells List'!G38,"") -> One weapon you touch is imbued with a sacred blessing. The weapon becomes magical and has +1 to attack and damage rolls for the duration.
A6: =IF(ISNUMBER(SEARCH("Priest",'Spells List'!$D45)),'Spells List'!A45,"") -> CR | B6: =IF(ISNUMBER(SEARCH("Priest",'Spells List'!$D45)),'Spells List'!B45,"") -> Light | C6: =IF(ISNUMBER(SEARCH("Priest",'Spells List'!$D45)),'Spells List'!C45,"") -> 1 | D6: =IF(ISNUMBER(SEARCH("Priest",'Spells List'!$D45)),'Spells List'!D45,"") -> Priest, Wizard | E6: =IF(ISNUMBER(SEARCH("Priest",'Spells List'!$D45)),'Spells List'!E45,"") -> 1 hour real time | F6: =IF(ISNUMBER(SEARCH("Priest",'Spells List'!$D45)),'Spells List'!F45,"") -> Close | G6: =IF(ISNUMBER(SEARCH("Priest",'Spells List'!$D45)),'Spells List'!G45,"") -> One object you touch glows with bright, heatless light, illuminating out to a near distance for 1 hour of real time.
A7: =IF(ISNUMBER(SEARCH("Priest",'Spells List'!$D60)),'Spells List'!A60,"") -> CR | B7: =IF(ISNUMBER(SEARCH("Priest",'Spells List'!$D60)),'Spells List'!B60,"") -> Protection From Evil | C7: =IF(ISNUMBER(SEARCH("Priest",'Spells List'!$D60)),'Spells List'!C60,"") -> 1 | D7: =IF(ISNUMBER(SEARCH("Priest",'Spells List'!$D60)),'Spells List'!D60,"") -> Priest, Wizard | E7: =IF(ISNUMBER(SEARCH("Priest",'Spells List'!$D60)),'Spells List'!E60,"") -> Focus | F7: =IF(ISNUMBER(SEARCH("Priest",'Spells List'!$D60)),'Spells List'!F60,"") -> Close | G7: =IF(ISNUMBER(SEARCH("Priest",'Spells List'!$D60)),'Spells List'!G60,"") -> For the spell's duration, chaotic beings have disadvantage on attack rolls and hostile spellcasting checks against the target. These beings also can't possess, compel, or beguile it. When cast on an already-possessed target, the possessing entity makes a CHA check vs. the last spellcasting check. On a failure, the entity is expelled.
A8: =IF(ISNUMBER(SEARCH("Priest",'Spells List'!$D66)),'Spells List'!A66,"") -> CR | B8: =IF(ISNUMBER(SEARCH("Priest",'Spells List'!$D66)),'Spells List'!B66,"") -> Shield Of Faith | C8: =IF(ISNUMBER(SEARCH("Priest",'Spells List'!$D66)),'Spells List'!C66,"") -> 1 | D8: =IF(ISNUMBER(SEARCH("Priest",'Spells List'!$D66)),'Spells List'!D66,"") -> Priest | E8: =IF(ISNUMBER(SEARCH("Priest",'Spells List'!$D66)),'Spells List'!E66,"") -> 5 rounds | F8: =IF(ISNUMBER(SEARCH("Priest",'Spells List'!$D66)),'Spells List'!F66,"") -> Self | G8: =IF(ISNUMBER(SEARCH("Priest",'Spells List'!$D66)),'Spells List'!G66,"") -> A protective force wrought of your holy conviction surrounds you. You gain a +2 bonus to your armor class for the duration.
A9: =IF(ISNUMBER(SEARCH("Priest",'Spells List'!$D74)),'Spells List'!A74,"") -> CR | B9: =IF(ISNUMBER(SEARCH("Priest",'Spells List'!$D74)),'Spells List'!B74,"") -> Turn Undead | C9: =IF(ISNUMBER(SEARCH("Priest",'Spells List'!$D74)),'Spells List'!C74,"") -> 1 | D9: =IF(ISNUMBER(SEARCH("Priest",'Spells List'!$D74)),'Spells List'!D74,"") -> Priest | E9: =IF(ISNUMBER(SEARCH("Priest",'Spells List'!$D74)),'Spells List'!E74,"") -> Instant | F9: =IF(ISNUMBER(SEARCH("Priest",'Spells List'!$D74)),'Spells List'!F74,"") -> Near | G9: =IF(ISNUMBER(SEARCH("Priest",'Spells List'!$D74)),'Spells List'!G74,"") -> You rebuke undead creatures, forcing them to flee. You must present a holy symbol to cast this spell. Undead creatures within near of you must make a CHA check vs. your spellcasting check. If a creature fails by 10+ points and is equal to or less than your level, it is destroyed. Otherwise, on a fail, it flees from you for 5 rounds.
A10: =IF(ISNUMBER(SEARCH("Priest",'Spells List'!$D9)),'Spells List'!A9,"") -> CR | B10: =IF(ISNUMBER(SEARCH("Priest",'Spells List'!$D9)),'Spells List'!B9,"") -> Bless | C10: =IF(ISNUMBER(SEARCH("Priest",'Spells List'!$D9)),'Spells List'!C9,"") -> 2 | D10: =IF(ISNUMBER(SEARCH("Priest",'Spells List'!$D9)),'Spells List'!D9,"") -> Priest | E10: =IF(ISNUMBER(SEARCH("Priest",'Spells List'!$D9)),'Spells List'!E9,"") -> Instant | F10: =IF(ISNUMBER(SEARCH("Priest",'Spells List'!$D9)),'Spells List'!F9,"") -> Close | G10: =IF(ISNUMBER(SEARCH("Priest",'Spells List'!$D9)),'Spells List'!G9,"") -> One creature you touch gains a luck token.
A11: =IF(ISNUMBER(SEARCH("Priest",'Spells List'!$D10)),'Spells List'!A10,"") -> CR | B11: =IF(ISNUMBER(SEARCH("Priest",'Spells List'!$D10)),'Spells List'!B10,"") -> Blind/Deafen | C11: =IF(ISNUMBER(SEARCH("Priest",'Spells List'!$D10)),'Spells List'!C10,"") -> 2 | D11: =IF(ISNUMBER(SEARCH("Priest",'Spells List'!$D10)),'Spells List'!D10,"") -> Priest | E11: =IF(ISNUMBER(SEARCH("Priest",'Spells List'!$D10)),'Spells List'!E10,"") -> Focus | F11: =IF(ISNUMBER(SEARCH("Priest",'Spells List'!$D10)),'Spells List'!F10,"") -> Near | G11: =IF(ISNUMBER(SEARCH("Priest",'Spells List'!$D10)),'Spells List'!G10,"") -> You utter a divine censure, blinding or deafening one creature you can see in range. The creature has disadvantage on tasks requiring the lost sense.
A12: =IF(ISNUMBER(SEARCH("Priest",'Spells List'!$D12)),'Spells List'!A12,"") -> CR | B12: =IF(ISNUMBER(SEARCH("Priest",'Spells List'!$D12)),'Spells List'!B12,"") -> Cleansing Weapon | C12: =IF(ISNUMBER(SEARCH("Priest",'Spells List'!$D12)),'Spells List'!C12,"") -> 2 | D12: =IF(ISNUMBER(SEARCH("Priest",'Spells List'!$D12)),'Spells List'!D12,"") -> Priest | E12: =IF(ISNUMBER(SEARCH("Priest",'Spells List'!$D12)),'Spells List'!E12,"") -> 5 rounds | F12: =IF(ISNUMBER(SEARCH("Priest",'Spells List'!$D12)),'Spells List'!F12,"") -> Close | G12: =IF(ISNUMBER(SEARCH("Priest",'Spells List'!$D12)),'Spells List'!G12,"") -> One weapon you touch is wreathed in purifying flames. It deals an additional 1d4 damage (1d6 vs. undead) for the duration.
A13: =IF(ISNUMBER(SEARCH("Priest",'Spells List'!$D69)),'Spells List'!A69,"") -> CR | B13: =IF(ISNUMBER(SEARCH("Priest",'Spells List'!$D69)),'Spells List'!B69,"") -> Smite | C13: =IF(ISNUMBER(SEARCH("Priest",'Spells List'!$D69)),'Spells List'!C69,"") -> 2 | D13: =IF(ISNUMBER(SEARCH("Priest",'Spells List'!$D69)),'Spells List'!D69,"") -> Priest | E13: =IF(ISNUMBER(SEARCH("Priest",'Spells List'!$D69)),'Spells List'!E69,"") -> Instant | F13: =IF(ISNUMBER(SEARCH("Priest",'Spells List'!$D69)),'Spells List'!F69,"") -> Near | G13: =IF(ISNUMBER(SEARCH("Priest",'Spells List'!$D69)),'Spells List'!G69,"") -> You call down punishing flames on a creature you can see within range. It takes 1d6 damage.
A14: =IF(ISNUMBER(SEARCH("Priest",'Spells List'!$D79)),'Spells List'!A79,"") -> CR | B14: =IF(ISNUMBER(SEARCH("Priest",'Spells List'!$D79)),'Spells List'!B79,"") -> Zone Of Truth | C14: =IF(ISNUMBER(SEARCH("Priest",'Spells List'!$D79)),'Spells List'!C79,"") -> 2 | D14: =IF(ISNUMBER(SEARCH("Priest",'Spells List'!$D79)),'Spells List'!D79,"") -> Priest | E14: =IF(ISNUMBER(SEARCH("Priest",'Spells List'!$D79)),'Spells List'!E79,"") -> Focus | F14: =IF(ISNUMBER(SEARCH("Priest",'Spells List'!$D79)),'Spells List'!F79,"") -> Near | G14: =IF(ISNUMBER(SEARCH("Priest",'Spells List'!$D79)),'Spells List'!G79,"") -> Compel a creature you can see to speak the truth while within range. They cannot utter a deliberate lie.
A15: =IF(ISNUMBER(SEARCH("Priest",'Spells List'!$D81)),'Spells List'!A81,"") -> CR | B15: =IF(ISNUMBER(SEARCH("Priest",'Spells List'!$D81)),'Spells List'!B81,"") -> Augury | C15: =IF(ISNUMBER(SEARCH("Priest",'Spells List'!$D81)),'Spells List'!C81,"") -> 2 | D15: =IF(ISNUMBER(SEARCH("Priest",'Spells List'!$D81)),'Spells List'!D81,"") -> Priest | E15: =IF(ISNUMBER(SEARCH("Priest",'Spells List'!$D81)),'Spells List'!E81,"") -> Instant | F15: =IF(ISNUMBER(SEARCH("Priest",'Spells List'!$D81)),'Spells List'!F81,"") -> Self | G15: =IF(ISNUMBER(SEARCH("Priest",'Spells List'!$D81)),'Spells List'!G81,"") -> You interpret the meaning of supernatural portents and omens. Ask the GM one question about a specific course of action. The GM says whether the action will lead to “weal” or “woe.”
A16: =IF(ISNUMBER(SEARCH("Priest",'Spells List'!$D14)),'Spells List'!A14,"") -> CR | B16: =IF(ISNUMBER(SEARCH("Priest",'Spells List'!$D14)),'Spells List'!B14,"") -> Command | C16: =IF(ISNUMBER(SEARCH("Priest",'Spells List'!$D14)),'Spells List'!C14,"") -> 3 | D16: =IF(ISNUMBER(SEARCH("Priest",'Spells List'!$D14)),'Spells List'!D14,"") -> Priest | E16: =IF(ISNUMBER(SEARCH("Priest",'Spells List'!$D14)),'Spells List'!E14,"") -> Focus | F16: =IF(ISNUMBER(SEARCH("Priest",'Spells List'!$D14)),'Spells List'!F14,"") -> Far | G16: =IF(ISNUMBER(SEARCH("Priest",'Spells List'!$D14)),'Spells List'!G14,"") -> You issue a verbal command to one creature in range who can understand you. The command must be one word, such as “kneel.” The target obeys the command for as long as you focus. If your command is ever directly harmful to the creature, it may make a Charisma check vs. your last spellcasting check. On a success, the spell ends.
A17: =IF(ISNUMBER(SEARCH("Priest",'Spells List'!$D43)),'Spells List'!A43,"") -> CR | B17: =IF(ISNUMBER(SEARCH("Priest",'Spells List'!$D43)),'Spells List'!B43,"") -> Lay To Rest | C17: =IF(ISNUMBER(SEARCH("Priest",'Spells List'!$D43)),'Spells List'!C43,"") -> 3 | D17: =IF(ISNUMBER(SEARCH("Priest",'Spells List'!$D43)),'Spells List'!D43,"") -> Priest | E17: =IF(ISNUMBER(SEARCH("Priest",'Spells List'!$D43)),'Spells List'!E43,"") -> Instant | F17: =IF(ISNUMBER(SEARCH("Priest",'Spells List'!$D43)),'Spells List'!F43,"") -> Close | G17: =IF(ISNUMBER(SEARCH("Priest",'Spells List'!$D43)),'Spells List'!G43,"") -> You instantly send an undead creature you touch to its final afterlife, destroying it utterly. You can target an undead creature of LV 9 or less.
A18: =IF(ISNUMBER(SEARCH("Priest",'Spells List'!$D50)),'Spells List'!A50,"") -> CR | B18: =IF(ISNUMBER(SEARCH("Priest",'Spells List'!$D50)),'Spells List'!B50,"") -> Mass Cure | C18: =IF(ISNUMBER(SEARCH("Priest",'Spells List'!$D50)),'Spells List'!C50,"") -> 3 | D18: =IF(ISNUMBER(SEARCH("Priest",'Spells List'!$D50)),'Spells List'!D50,"") -> Priest | E18: =IF(ISNUMBER(SEARCH("Priest",'Spells List'!$D50)),'Spells List'!E50,"") -> Instant | F18: =IF(ISNUMBER(SEARCH("Priest",'Spells List'!$D50)),'Spells List'!F50,"") -> Near | G18: =IF(ISNUMBER(SEARCH("Priest",'Spells List'!$D50)),'Spells List'!G50,"") -> All allies within near range of you regain 2d6 hit points.
A19: =IF(ISNUMBER(SEARCH("Priest",'Spells List'!$D61)),'Spells List'!A61,"") -> CR | B19: =IF(ISNUMBER(SEARCH("Priest",'Spells List'!$D61)),'Spells List'!B61,"") -> Rebuke Unholy | C19: =IF(ISNUMBER(SEARCH("Priest",'Spells List'!$D61)),'Spells List'!C61,"") -> 3 | D19: =IF(ISNUMBER(SEARCH("Priest",'Spells List'!$D61)),'Spells List'!D61,"") -> Priest | E19: =IF(ISNUMBER(SEARCH("Priest",'Spells List'!$D61)),'Spells List'!E61,"") -> Instant | F19: =IF(ISNUMBER(SEARCH("Priest",'Spells List'!$D61)),'Spells List'!F61,"") -> Near | G19: =IF(ISNUMBER(SEARCH("Priest",'Spells List'!$D61)),'Spells List'!G61,"") -> Rebuke creatures who oppose your alignment, forcing them to flee. You must present a holy symbol to cast this spell. If you are lawful or neutral, this spell affects demons, devils, and outsiders. If you are chaotic, this spell affects angels and natural creatures of the wild. Affected creatures within near of you must make a CHA check vs. your spellcasting check. If a creature fails by 10+ points and is equal to or less than your level, it is destroyed. Otherwise, on a fail, it flees from you for 5 rounds.
A20: =IF(ISNUMBER(SEARCH("Priest",'Spells List'!$D64)),'Spells List'!A64,"") -> CR | B20: =IF(ISNUMBER(SEARCH("Priest",'Spells List'!$D64)),'Spells List'!B64,"") -> Restoration | C20: =IF(ISNUMBER(SEARCH("Priest",'Spells List'!$D64)),'Spells List'!C64,"") -> 3 | D20: =IF(ISNUMBER(SEARCH("Priest",'Spells List'!$D64)),'Spells List'!D64,"") -> Priest | E20: =IF(ISNUMBER(SEARCH("Priest",'Spells List'!$D64)),'Spells List'!E64,"") -> Instant | F20: =IF(ISNUMBER(SEARCH("Priest",'Spells List'!$D64)),'Spells List'!F64,"") -> Close | G20: =IF(ISNUMBER(SEARCH("Priest",'Spells List'!$D64)),'Spells List'!G64,"") -> With the touch of your hands, you expunge curses and illnesses. One curse, illness, or affliction of your choice affecting the target creature ends.
A21: =IF(ISNUMBER(SEARCH("Priest",'Spells List'!$D88)),'Spells List'!A88,"") -> CR | B21: =IF(ISNUMBER(SEARCH("Priest",'Spells List'!$D88)),'Spells List'!B88,"") -> Speak With Dead | C21: =IF(ISNUMBER(SEARCH("Priest",'Spells List'!$D88)),'Spells List'!C88,"") -> 3 | D21: =IF(ISNUMBER(SEARCH("Priest",'Spells List'!$D88)),'Spells List'!D88,"") -> Priest, Wizard | E21: =IF(ISNUMBER(SEARCH("Priest",'Spells List'!$D88)),'Spells List'!E88,"") -> Instant | F21: =IF(ISNUMBER(SEARCH("Priest",'Spells List'!$D88)),'Spells List'!F88,"") -> Close | G21: =IF(ISNUMBER(SEARCH("Priest",'Spells List'!$D88)),'Spells List'!G88,"") -> A dead body you touch answers your questions in a distant, wheezing voice. You can ask the dead body up to three yes or no questions (one at a time). The GM truthfully answers "yes" or "no" to each. If you cast this spell more than once in 24 hours, treat a failed spellcasting check for it as a critical failure, instead.
A22: =IF(ISNUMBER(SEARCH("Priest",'Spells List'!$D15)),'Spells List'!A15,"") -> CR | B22: =IF(ISNUMBER(SEARCH("Priest",'Spells List'!$D15)),'Spells List'!B15,"") -> Commune | C22: =IF(ISNUMBER(SEARCH("Priest",'Spells List'!$D15)),'Spells List'!C15,"") -> 4 | D22: =IF(ISNUMBER(SEARCH("Priest",'Spells List'!$D15)),'Spells List'!D15,"") -> Priest | E22: =IF(ISNUMBER(SEARCH("Priest",'Spells List'!$D15)),'Spells List'!E15,"") -> Instant | F22: =IF(ISNUMBER(SEARCH("Priest",'Spells List'!$D15)),'Spells List'!F15,"") -> Self | G22: =IF(ISNUMBER(SEARCH("Priest",'Spells List'!$D15)),'Spells List'!G15,"") -> You seek your god's counsel. Ask the GM up to three yes or no questions. The GM truthfully answers "yes" or "no" to each. If you cast this spell more than once in 24 hours, treat a failed spellcasting check for it as a critical failure, instead.
A23: =IF(ISNUMBER(SEARCH("Priest",'Spells List'!$D17)),'Spells List'!A17,"") -> CR | B23: =IF(ISNUMBER(SEARCH("Priest",'Spells List'!$D17)),'Spells List'!B17,"") -> Control Water | C23: =IF(ISNUMBER(SEARCH("Priest",'Spells List'!$D17)),'Spells List'!C17,"") -> 4 | D23: =IF(ISNUMBER(SEARCH("Priest",'Spells List'!$D17)),'Spells List'!D17,"") -> Priest, Wizard | E23: =IF(ISNUMBER(SEARCH("Priest",'Spells List'!$D17)),'Spells List'!E17,"") -> Focus | F23: =IF(ISNUMBER(SEARCH("Priest",'Spells List'!$D17)),'Spells List'!F17,"") -> Far | G23: =IF(ISNUMBER(SEARCH("Priest",'Spells List'!$D17)),'Spells List'!G17,"") -> You move and shape water. You can cause a section of water up to 100 feet in width and depth to change shape, defy gravity, or flow in a different direction.
A24: =IF(ISNUMBER(SEARCH("Priest",'Spells List'!$D30)),'Spells List'!A30,"") -> CR | B24: =IF(ISNUMBER(SEARCH("Priest",'Spells List'!$D30)),'Spells List'!B30,"") -> Flame Strike | C24: =IF(ISNUMBER(SEARCH("Priest",'Spells List'!$D30)),'Spells List'!C30,"") -> 4 | D24: =IF(ISNUMBER(SEARCH("Priest",'Spells List'!$D30)),'Spells List'!D30,"") -> Priest | E24: =IF(ISNUMBER(SEARCH("Priest",'Spells List'!$D30)),'Spells List'!E30,"") -> Instant | F24: =IF(ISNUMBER(SEARCH("Priest",'Spells List'!$D30)),'Spells List'!F30,"") -> Far | G24: =IF(ISNUMBER(SEARCH("Priest",'Spells List'!$D30)),'Spells List'!G30,"") -> You call down a holy pillar of fire, immolating one creature you can see within range. The target takes 2d6 damage.
A25: =IF(ISNUMBER(SEARCH("Priest",'Spells List'!$D54)),'Spells List'!A54,"") -> CR | B25: =IF(ISNUMBER(SEARCH("Priest",'Spells List'!$D54)),'Spells List'!B54,"") -> Pillar Of Salt | C25: =IF(ISNUMBER(SEARCH("Priest",'Spells List'!$D54)),'Spells List'!C54,"") -> 4 | D25: =IF(ISNUMBER(SEARCH("Priest",'Spells List'!$D54)),'Spells List'!D54,"") -> Priest | E25: =IF(ISNUMBER(SEARCH("Priest",'Spells List'!$D54)),'Spells List'!E54,"") -> Focus | F25: =IF(ISNUMBER(SEARCH("Priest",'Spells List'!$D54)),'Spells List'!F54,"") -> Near | G25: =IF(ISNUMBER(SEARCH("Priest",'Spells List'!$D54)),'Spells List'!G54,"") -> A creature you target turns into a statue made of hardened salt. You can target a creature you can see of LV 5 or less. If you focus on this spell for 3 rounds in a row, the transformation becomes permanent.
A26: =IF(ISNUMBER(SEARCH("Priest",'Spells List'!$D62)),'Spells List'!A62,"") -> CR | B26: =IF(ISNUMBER(SEARCH("Priest",'Spells List'!$D62)),'Spells List'!B62,"") -> Regenerate | C26: =IF(ISNUMBER(SEARCH("Priest",'Spells List'!$D62)),'Spells List'!C62,"") -> 4 | D26: =IF(ISNUMBER(SEARCH("Priest",'Spells List'!$D62)),'Spells List'!D62,"") -> Priest | E26: =IF(ISNUMBER(SEARCH("Priest",'Spells List'!$D62)),'Spells List'!E62,"") -> Focus | F26: =IF(ISNUMBER(SEARCH("Priest",'Spells List'!$D62)),'Spells List'!F62,"") -> Close | G26: =IF(ISNUMBER(SEARCH("Priest",'Spells List'!$D62)),'Spells List'!G62,"") -> A creature you touch regains 1d4 hit points on your turn for the duration. This spell also regrows lost body parts.
A27: =IF(ISNUMBER(SEARCH("Priest",'Spells List'!$D78)),'Spells List'!A78,"") -> CR | B27: =IF(ISNUMBER(SEARCH("Priest",'Spells List'!$D78)),'Spells List'!B78,"") -> Wrath | C27: =IF(ISNUMBER(SEARCH("Priest",'Spells List'!$D78)),'Spells List'!C78,"") -> 4 | D27: =IF(ISNUMBER(SEARCH("Priest",'Spells List'!$D78)),'Spells List'!D78,"") -> Priest | E27: =IF(ISNUMBER(SEARCH("Priest",'Spells List'!$D78)),'Spells List'!E78,"") -> 10 rounds | F27: =IF(ISNUMBER(SEARCH("Priest",'Spells List'!$D78)),'Spells List'!F78,"") -> Self | G27: =IF(ISNUMBER(SEARCH("Priest",'Spells List'!$D78)),'Spells List'!G78,"") -> Weapons become magical +2 and deal an additional d8 damage for the spell's duration.
A28: =IF(ISNUMBER(SEARCH("Priest",'Spells List'!$D24)),'Spells List'!A24,"") -> CR | B28: =IF(ISNUMBER(SEARCH("Priest",'Spells List'!$D24)),'Spells List'!B24,"") -> Divine Vengeance | C28: =IF(ISNUMBER(SEARCH("Priest",'Spells List'!$D24)),'Spells List'!C24,"") -> 5 | D28: =IF(ISNUMBER(SEARCH("Priest",'Spells List'!$D24)),'Spells List'!D24,"") -> Priest | E28: =IF(ISNUMBER(SEARCH("Priest",'Spells List'!$D24)),'Spells List'!E24,"") -> 10 rounds | F28: =IF(ISNUMBER(SEARCH("Priest",'Spells List'!$D24)),'Spells List'!F24,"") -> Self | G28: =IF(ISNUMBER(SEARCH("Priest",'Spells List'!$D24)),'Spells List'!G24,"") -> You become the divine avatar of your god's wrath, wreathed in holy flames or a black aura of smoldering corruption. For the spell's duration, you can fly a near distance, your weapons are magical, and you have a +4 bonus to your weapon attacks and damage.
A29: =IF(ISNUMBER(SEARCH("Priest",'Spells List'!$D25)),'Spells List'!A25,"") -> CR | B29: =IF(ISNUMBER(SEARCH("Priest",'Spells List'!$D25)),'Spells List'!B25,"") -> Dominion | C29: =IF(ISNUMBER(SEARCH("Priest",'Spells List'!$D25)),'Spells List'!C25,"") -> 5 | D29: =IF(ISNUMBER(SEARCH("Priest",'Spells List'!$D25)),'Spells List'!D25,"") -> Priest | E29: =IF(ISNUMBER(SEARCH("Priest",'Spells List'!$D25)),'Spells List'!E25,"") -> 10 rounds | F29: =IF(ISNUMBER(SEARCH("Priest",'Spells List'!$D25)),'Spells List'!F25,"") -> Near | G29: =IF(ISNUMBER(SEARCH("Priest",'Spells List'!$D25)),'Spells List'!G25,"") -> Mighty beings come to your aid. The beings must have a combined total of 16 levels or less. Chaotic PCs summon demons/devils, and lawful or neutral PCs summon angels. The beings act of free will to aid you on your turn. After 10 rounds, they return to their realms. You cannot cast this spell again until you complete penance.
A30: =IF(ISNUMBER(SEARCH("Priest",'Spells List'!$D34)),'Spells List'!A34,"") -> CR | B30: =IF(ISNUMBER(SEARCH("Priest",'Spells List'!$D34)),'Spells List'!B34,"") -> Heal | C30: =IF(ISNUMBER(SEARCH("Priest",'Spells List'!$D34)),'Spells List'!C34,"") -> 5 | D30: =IF(ISNUMBER(SEARCH("Priest",'Spells List'!$D34)),'Spells List'!D34,"") -> Priest | E30: =IF(ISNUMBER(SEARCH("Priest",'Spells List'!$D34)),'Spells List'!E34,"") -> Instant | F30: =IF(ISNUMBER(SEARCH("Priest",'Spells List'!$D34)),'Spells List'!F34,"") -> Close | G30: =IF(ISNUMBER(SEARCH("Priest",'Spells List'!$D34)),'Spells List'!G34,"") -> One creature you touch is healed to full hit points. You cannot cast this spell again until you complete a rest.
A31: =IF(ISNUMBER(SEARCH("Priest",'Spells List'!$D41)),'Spells List'!A41,"") -> CR | B31: =IF(ISNUMBER(SEARCH("Priest",'Spells List'!$D41)),'Spells List'!B41,"") -> Judgment | C31: =IF(ISNUMBER(SEARCH("Priest",'Spells List'!$D41)),'Spells List'!C41,"") -> 5 | D31: =IF(ISNUMBER(SEARCH("Priest",'Spells List'!$D41)),'Spells List'!D41,"") -> Priest | E31: =IF(ISNUMBER(SEARCH("Priest",'Spells List'!$D41)),'Spells List'!E41,"") -> 5 rounds | F31: =IF(ISNUMBER(SEARCH("Priest",'Spells List'!$D41)),'Spells List'!F41,"") -> Close | G31: =IF(ISNUMBER(SEARCH("Priest",'Spells List'!$D41)),'Spells List'!G41,"") -> You instantly banish a creature you touch, sending it and all possessions it carries to face the judgment of your god. You can banish an intelligent creature of LV 10 or less. When the creature returns in 5 rounds, it has been healed to full hit points if its deeds pleased your god. It has been reduced to 1 hit point if its deeds angered your god. If your god can't judge its actions, it is unchanged.
A32: =IF(ISNUMBER(SEARCH("Priest",'Spells List'!$D55)),'Spells List'!A55,"") -> CR | B32: =IF(ISNUMBER(SEARCH("Priest",'Spells List'!$D55)),'Spells List'!B55,"") -> Plane Shift | C32: =IF(ISNUMBER(SEARCH("Priest",'Spells List'!$D55)),'Spells List'!C55,"") -> 5 | D32: =IF(ISNUMBER(SEARCH("Priest",'Spells List'!$D55)),'Spells List'!D55,"") -> Priest, Wizard | E32: =IF(ISNUMBER(SEARCH("Priest",'Spells List'!$D55)),'Spells List'!E55,"") -> Instant | F32: =IF(ISNUMBER(SEARCH("Priest",'Spells List'!$D55)),'Spells List'!F55,"") -> Close | G32: =IF(ISNUMBER(SEARCH("Priest",'Spells List'!$D55)),'Spells List'!G55,"") -> You fold space and time, transporting yourself and all willing creatures within close range to a location on another plane of your choice. Unless you have been to your intended location before, you appear in a random place on the destination plane.
A33: =IF(ISNUMBER(SEARCH("Priest",'Spells List'!$D58)),'Spells List'!A58,"") -> CR | B33: =IF(ISNUMBER(SEARCH("Priest",'Spells List'!$D58)),'Spells List'!B58,"") -> Prophecy | C33: =IF(ISNUMBER(SEARCH("Priest",'Spells List'!$D58)),'Spells List'!C58,"") -> 5 | D33: =IF(ISNUMBER(SEARCH("Priest",'Spells List'!$D58)),'Spells List'!D58,"") -> Priest | E33: =IF(ISNUMBER(SEARCH("Priest",'Spells List'!$D58)),'Spells List'!E58,"") -> Instant | F33: =IF(ISNUMBER(SEARCH("Priest",'Spells List'!$D58)),'Spells List'!F58,"") -> Self | G33: =IF(ISNUMBER(SEARCH("Priest",'Spells List'!$D58)),'Spells List'!G58,"") -> Commune directly with your god for guidance. Ask the GM one question. The GM answers the question truthfully using the knowledge your god possesses. You cannot cast this spell again until you complete penance.

Sheet Wizard
C1: Click button/link to filter view. Updated May 7th, 2023. Submit Errors & Omissions.
E2: =HYPERLINK("https://docs.google.com/spreadsheets/d/1LNrLMVYyd306jR2KTeo3D2aKOXg3gN7ZjqvpuqQwcfE/edit#gid=0",IMAGE("https://docs.google.com/drawings/d/e/2PACX-1vSWClHE0jSQi8W_5mD2IrBvSKEkkfMPT69j4Ud4x8UxL4f1yPsoBqNRTdzxnNqPXYSQXHzXA1SwLQ_Q/pub?w=678&h=521")) | F2: =HYPERLINK("https://docs.google.com/spreadsheets/d/1LNrLMVYyd306jR2KTeo3D2aKOXg3gN7ZjqvpuqQwcfE/edit#gid=1078251919",IMAGE("https://docs.google.com/drawings/d/e/2PACX-1vSI-rNq8_u7Ei3MBcQcVdkIvFG4mUYg4tFCfq76fmmX-xsW4ZO-wmkMDQ_Vamy0YNENa-aOf4LZEcVZ/pub?w=778&h=599")) | G2: =HYPERLINK("https://docs.google.com/spreadsheets/d/1LNrLMVYyd306jR2KTeo3D2aKOXg3gN7ZjqvpuqQwcfE/edit#gid=208973905",IMAGE("https://docs.google.com/drawings/d/e/2PACX-1vSiJRXVDFJLq7jiqpjBP3Sv1KhAYxN8ga97zqGh7gmWfal60Q4Tx3JxCBOw3tjaArSwiqnvasaZVMTG/pub?w=595&h=458")) | H2: Submit your own homebrewed spells for inclusion! | I2: =HYPERLINK("https://bit.ly/3AUMaH6",IMAGE("https://docs.google.com/drawings/d/e/2PACX-1vTVp531OswDqgLbtAH17IZ8cCok9zrVPFK34jqpyR8JTRafQasvw437G-DgGEmB6SE9vxEhKK7WEhfJ/pub?w=660&h=513"))
A3: Source | B3: Spell Name | C3: Tier # | D3: Spell Type | E3: Duration | F3: Range | G3: Description
A4: =IF(ISNUMBER(SEARCH("Wizard",'Spells List'!$D5)),'Spells List'!A5,"") -> CR | B4: =IF(ISNUMBER(SEARCH("Wizard",'Spells List'!$D5)),'Spells List'!B5,"") -> Alarm | C4: =IF(ISNUMBER(SEARCH("Wizard",'Spells List'!$D5)),'Spells List'!C5,"") -> 1 | D4: =IF(ISNUMBER(SEARCH("Wizard",'Spells List'!$D5)),'Spells List'!D5,"") -> Wizard | E4: =IF(ISNUMBER(SEARCH("Wizard",'Spells List'!$D5)),'Spells List'!E5,"") -> 1 day | F4: =IF(ISNUMBER(SEARCH("Wizard",'Spells List'!$D5)),'Spells List'!F5,"") -> Close | G4: =IF(ISNUMBER(SEARCH("Wizard",'Spells List'!$D5)),'Spells List'!G5,"") -> Send a strobing orb of energy streaking toward a target within range. Choose an energy type from fire, cold, or electricity. The orb deals 3d8 damage and delivers a concussive blast of the chosen energy type. If the energy type is anathema to the target's existence, the orb deals double damage to it.
A5: =IF(ISNUMBER(SEARCH("Wizard",'Spells List'!$D11)),'Spells List'!A11,"") -> CR | B5: =IF(ISNUMBER(SEARCH("Wizard",'Spells List'!$D11)),'Spells List'!B11,"") -> Burning Hands | C5: =IF(ISNUMBER(SEARCH("Wizard",'Spells List'!$D11)),'Spells List'!C11,"") -> 1 | D5: =IF(ISNUMBER(SEARCH("Wizard",'Spells List'!$D11)),'Spells List'!D11,"") -> Wizard | E5: =IF(ISNUMBER(SEARCH("Wizard",'Spells List'!$D11)),'Spells List'!E11,"") -> Instant | F5: =IF(ISNUMBER(SEARCH("Wizard",'Spells List'!$D11)),'Spells List'!F11,"") -> Close | G5: =IF(ISNUMBER(SEARCH("Wizard",'Spells List'!$D11)),'Spells List'!G11,"") -> You spread your fingers with thumbs touching, unleashing a circle of flame that roars out to a close area around where you stand. Creatures within the area of effect take 1d6 damage, and flammable objects catch fire.
A6: =IF(ISNUMBER(SEARCH("Wizard",'Spells List'!$D20)),'Spells List'!A20,"") -> CR | B6: =IF(ISNUMBER(SEARCH("Wizard",'Spells List'!$D20)),'Spells List'!B20,"") -> Detect Magic | C6: =IF(ISNUMBER(SEARCH("Wizard",'Spells List'!$D20)),'Spells List'!C20,"") -> 1 | D6: =IF(ISNUMBER(SEARCH("Wizard",'Spells List'!$D20)),'Spells List'!D20,"") -> Wizard | E6: =IF(ISNUMBER(SEARCH("Wizard",'Spells List'!$D20)),'Spells List'!E20,"") -> Focus | F6: =IF(ISNUMBER(SEARCH("Wizard",'Spells List'!$D20)),'Spells List'!F20,"") -> Near | G6: =IF(ISNUMBER(SEARCH("Wizard",'Spells List'!$D20)),'Spells List'!G20,"") -> You can sense the presence of magic within near range for the spell's duration. If you focus for two rounds, you discern its general properties. Full barriers block this spell.
A7: =IF(ISNUMBER(SEARCH("Wizard",'Spells List'!$D27)),'Spells List'!A27,"") -> CR | B7: =IF(ISNUMBER(SEARCH("Wizard",'Spells List'!$D27)),'Spells List'!B27,"") -> Feather Fall | C7: =IF(ISNUMBER(SEARCH("Wizard",'Spells List'!$D27)),'Spells List'!C27,"") -> 1 | D7: =IF(ISNUMBER(SEARCH("Wizard",'Spells List'!$D27)),'Spells List'!D27,"") -> Wizard | E7: =IF(ISNUMBER(SEARCH("Wizard",'Spells List'!$D27)),'Spells List'!E27,"") -> Instant | F7: =IF(ISNUMBER(SEARCH("Wizard",'Spells List'!$D27)),'Spells List'!F27,"") -> Self | G7: =IF(ISNUMBER(SEARCH("Wizard",'Spells List'!$D27)),'Spells List'!G27,"") -> You may make an attempt to cast this spell when you fall. Your rate of descent slows so that you land safely on your feet.
A8: =IF(ISNUMBER(SEARCH("Wizard",'Spells List'!$D31)),'Spells List'!A31,"") -> CR | B8: =IF(ISNUMBER(SEARCH("Wizard",'Spells List'!$D31)),'Spells List'!B31,"") -> Floating Disk | C8: =IF(ISNUMBER(SEARCH("Wizard",'Spells List'!$D31)),'Spells List'!C31,"") -> 1 | D8: =IF(ISNUMBER(SEARCH("Wizard",'Spells List'!$D31)),'Spells List'!D31,"") -> Wizard | E8: =IF(ISNUMBER(SEARCH("Wizard",'Spells List'!$D31)),'Spells List'!E31,"") -> 10 rounds | F8: =IF(ISNUMBER(SEARCH("Wizard",'Spells List'!$D31)),'Spells List'!F31,"") -> Near | G8: =IF(ISNUMBER(SEARCH("Wizard",'Spells List'!$D31)),'Spells List'!G31,"") -> You create a floating, circular disk of force with a concave center. It can carry up to 20 gear slots. It hovers at waist level and automatically stays within near of you. It can’t cross over drop-offs or pits taller than a human.
A9: =IF(ISNUMBER(SEARCH("Wizard",'Spells List'!$D37)),'Spells List'!A37,"") -> CR | B9: =IF(ISNUMBER(SEARCH("Wizard",'Spells List'!$D37)),'Spells List'!B37,"") -> Hold Portal | C9: =IF(ISNUMBER(SEARCH("Wizard",'Spells List'!$D37)),'Spells List'!C37,"") -> 1 | D9: =IF(ISNUMBER(SEARCH("Wizard",'Spells List'!$D37)),'Spells List'!D37,"") -> Wizard | E9: =IF(ISNUMBER(SEARCH("Wizard",'Spells List'!$D37)),'Spells List'!E37,"") -> 10 rounds | F9: =IF(ISNUMBER(SEARCH("Wizard",'Spells List'!$D37)),'Spells List'!F37,"") -> Near | G9: =IF(ISNUMBER(SEARCH("Wizard",'Spells List'!$D37)),'Spells List'!G37,"") -> You magically hold a portal closed for the duration. A creature must make a successful STR check vs. your spellcasting check to open the portal. The knock spell ends this spell.
A10: =IF(ISNUMBER(SEARCH("Wizard",'Spells List'!$D45)),'Spells List'!A45,"") -> CR | B10: =IF(ISNUMBER(SEARCH("Wizard",'Spells List'!$D45)),'Spells List'!B45,"") -> Light | C10: =IF(ISNUMBER(SEARCH("Wizard",'Spells List'!$D45)),'Spells List'!C45,"") -> 1 | D10: =IF(ISNUMBER(SEARCH("Wizard",'Spells List'!$D45)),'Spells List'!D45,"") -> Priest, Wizard | E10: =IF(ISNUMBER(SEARCH("Wizard",'Spells List'!$D45)),'Spells List'!E45,"") -> 1 hour real time | F10: =IF(ISNUMBER(SEARCH("Wizard",'Spells List'!$D45)),'Spells List'!F45,"") -> Close | G10: =IF(ISNUMBER(SEARCH("Wizard",'Spells List'!$D45)),'Spells List'!G45,"") -> One object you touch glows with bright, heatless light, illuminating out to a near distance for 1 hour of real time.
A11: =IF(ISNUMBER(SEARCH("Wizard",'Spells List'!$D47)),'Spells List'!A47,"") -> CR | B11: =IF(ISNUMBER(SEARCH("Wizard",'Spells List'!$D47)),'Spells List'!B47,"") -> Mage Armor | C11: =IF(ISNUMBER(SEARCH("Wizard",'Spells List'!$D47)),'Spells List'!C47,"") -> 1 | D11: =IF(ISNUMBER(SEARCH("Wizard",'Spells List'!$D47)),'Spells List'!D47,"") -> Wizard | E11: =IF(ISNUMBER(SEARCH("Wizard",'Spells List'!$D47)),'Spells List'!E47,"") -> 10 rounds | F11: =IF(ISNUMBER(SEARCH("Wizard",'Spells List'!$D47)),'Spells List'!F47,"") -> Self | G11: =IF(ISNUMBER(SEARCH("Wizard",'Spells List'!$D47)),'Spells List'!G47,"") -> An invisible layer of magical force protects your vitals. Your armor class becomes 14 (18 on a critical spellcasting check) for the spell’s duration.
A12: =IF(ISNUMBER(SEARCH("Wizard",'Spells List'!$D49)),'Spells List'!A49,"") -> CR | B12: =IF(ISNUMBER(SEARCH("Wizard",'Spells List'!$D49)),'Spells List'!B49,"") -> Magic Missile | C12: =IF(ISNUMBER(SEARCH("Wizard",'Spells List'!$D49)),'Spells List'!C49,"") -> 1 | D12: =IF(ISNUMBER(SEARCH("Wizard",'Spells List'!$D49)),'Spells List'!D49,"") -> Wizard | E12: =IF(ISNUMBER(SEARCH("Wizard",'Spells List'!$D49)),'Spells List'!E49,"") -> Instant | F12: =IF(ISNUMBER(SEARCH("Wizard",'Spells List'!$D49)),'Spells List'!F49,"") -> Far | G12: =IF(ISNUMBER(SEARCH("Wizard",'Spells List'!$D49)),'Spells List'!G49,"") -> You have advantage on your check to cast this spell. A glowing bolt of force streaks from your open hand, dealing 1d4 damage to one target.
A13: =IF(ISNUMBER(SEARCH("Wizard",'Spells List'!$D60)),'Spells List'!A60,"") -> CR | B13: =IF(ISNUMBER(SEARCH("Wizard",'Spells List'!$D60)),'Spells List'!B60,"") -> Protection From Evil | C13: =IF(ISNUMBER(SEARCH("Wizard",'Spells List'!$D60)),'Spells List'!C60,"") -> 1 | D13: =IF(ISNUMBER(SEARCH("Wizard",'Spells List'!$D60)),'Spells List'!D60,"") -> Priest, Wizard | E13: =IF(ISNUMBER(SEARCH("Wizard",'Spells List'!$D60)),'Spells List'!E60,"") -> Focus | F13: =IF(ISNUMBER(SEARCH("Wizard",'Spells List'!$D60)),'Spells List'!F60,"") -> Close | G13: =IF(ISNUMBER(SEARCH("Wizard",'Spells List'!$D60)),'Spells List'!G60,"") -> For the spell's duration, chaotic beings have disadvantage on attack rolls and hostile spellcasting checks against the target. These beings also can't possess, compel, or beguile it. When cast on an already-possessed target, the possessing entity makes a CHA check vs. the last spellcasting check. On a failure, the entity is expelled.
A14: =IF(ISNUMBER(SEARCH("Wizard",'Spells List'!$D68)),'Spells List'!A68,"") -> CR | B14: =IF(ISNUMBER(SEARCH("Wizard",'Spells List'!$D68)),'Spells List'!B68,"") -> Sleep | C14: =IF(ISNUMBER(SEARCH("Wizard",'Spells List'!$D68)),'Spells List'!C68,"") -> 1 | D14: =IF(ISNUMBER(SEARCH("Wizard",'Spells List'!$D68)),'Spells List'!D68,"") -> Wizard | E14: =IF(ISNUMBER(SEARCH("Wizard",'Spells List'!$D68)),'Spells List'!E68,"") -> Instant | F14: =IF(ISNUMBER(SEARCH("Wizard",'Spells List'!$D68)),'Spells List'!F68,"") -> Near | G14: =IF(ISNUMBER(SEARCH("Wizard",'Spells List'!$D68)),'Spells List'!G68,"") -> You weave a lulling spell that fills a near-sized cube extending from you. Living creatures in the area of effect fall into a deep sleep if they are LV 2 or less.
A15: =IF(ISNUMBER(SEARCH("Wizard",'Spells List'!$D82)),'Spells List'!A82,"") -> CR | B15: =IF(ISNUMBER(SEARCH("Wizard",'Spells List'!$D82)),'Spells List'!B82,"") -> Charm Person | C15: =IF(ISNUMBER(SEARCH("Wizard",'Spells List'!$D82)),'Spells List'!C82,"") -> 1 | D15: =IF(ISNUMBER(SEARCH("Wizard",'Spells List'!$D82)),'Spells List'!D82,"") -> Wizard | E15: =IF(ISNUMBER(SEARCH("Wizard",'Spells List'!$D82)),'Spells List'!E82,"") -> 1d8 days | F15: =IF(ISNUMBER(SEARCH("Wizard",'Spells List'!$D82)),'Spells List'!F82,"") -> Near | G15: =IF(ISNUMBER(SEARCH("Wizard",'Spells List'!$D82)),'Spells List'!G82,"") -> You magically beguile one humanoid of LV 2 or less within near range, who regards you as a friend for the duration. The spell ends if you or your allies do anything harmful to the target. The target knows it was magically charmed after the spell ends.
A16: =IF(ISNUMBER(SEARCH("Wizard",'Spells List'!$D4)),'Spells List'!A4,"") -> CR | B16: =IF(ISNUMBER(SEARCH("Wizard",'Spells List'!$D4)),'Spells List'!B4,"") -> Acid Arrow | C16: =IF(ISNUMBER(SEARCH("Wizard",'Spells List'!$D4)),'Spells List'!C4,"") -> 2 | D16: =IF(ISNUMBER(SEARCH("Wizard",'Spells List'!$D4)),'Spells List'!D4,"") -> Wizard | E16: =IF(ISNUMBER(SEARCH("Wizard",'Spells List'!$D4)),'Spells List'!E4,"") -> Focus | F16: =IF(ISNUMBER(SEARCH("Wizard",'Spells List'!$D4)),'Spells List'!F4,"") -> Far | G16: =IF(ISNUMBER(SEARCH("Wizard",'Spells List'!$D4)),'Spells List'!G4,"") -> You conjure a corrosive bolt that hits one foe, dealing 1d6 damage a round. The bolt remains in the target for as long as you focus.
A17: =IF(ISNUMBER(SEARCH("Wizard",'Spells List'!$D21)),'Spells List'!A21,"") -> CR | B17: =IF(ISNUMBER(SEARCH("Wizard",'Spells List'!$D21)),'Spells List'!B21,"") -> Detect Thoughts | C17: =IF(ISNUMBER(SEARCH("Wizard",'Spells List'!$D21)),'Spells List'!C21,"") -> 2 | D17: =IF(ISNUMBER(SEARCH("Wizard",'Spells List'!$D21)),'Spells List'!D21,"") -> Wizard | E17: =IF(ISNUMBER(SEARCH("Wizard",'Spells List'!$D21)),'Spells List'!E21,"") -> Focus | F17: =IF(ISNUMBER(SEARCH("Wizard",'Spells List'!$D21)),'Spells List'!F21,"") -> Near | G17: =IF(ISNUMBER(SEARCH("Wizard",'Spells List'!$D21)),'Spells List'!G21,"") -> You peer into the mind of one creature you can see within range. Each round, you learn the target’s immediate thoughts. On its turn, the target makes a Wisdom check vs. your last spellcasting check. If the target succeeds, it notices your presence in its mind and the spell ends. "Magic is simply the art of doing and undoing." -Creeg, human wizard
A18: =IF(ISNUMBER(SEARCH("Wizard",'Spells List'!$D29)),'Spells List'!A29,"") -> CR | B18: =IF(ISNUMBER(SEARCH("Wizard",'Spells List'!$D29)),'Spells List'!B29,"") -> Fixed Object | C18: =IF(ISNUMBER(SEARCH("Wizard",'Spells List'!$D29)),'Spells List'!C29,"") -> 2 | D18: =IF(ISNUMBER(SEARCH("Wizard",'Spells List'!$D29)),'Spells List'!D29,"") -> Wizard | E18: =IF(ISNUMBER(SEARCH("Wizard",'Spells List'!$D29)),'Spells List'!E29,"") -> 5 rounds | F18: =IF(ISNUMBER(SEARCH("Wizard",'Spells List'!$D29)),'Spells List'!F29,"") -> Close | G18: =IF(ISNUMBER(SEARCH("Wizard",'Spells List'!$D29)),'Spells List'!G29,"") -> An object you touch that weighs no more than 5 pounds becomes fixed in its current location. It can support up to 5,000 pounds of weight for the duration of the spell.
A19: =IF(ISNUMBER(SEARCH("Wizard",'Spells List'!$D36)),'Spells List'!A36,"") -> CR | B19: =IF(ISNUMBER(SEARCH("Wizard",'Spells List'!$D36)),'Spells List'!B36,"") -> Hold Person | C19: =IF(ISNUMBER(SEARCH("Wizard",'Spells List'!$D36)),'Spells List'!C36,"") -> 2 | D19: =IF(ISNUMBER(SEARCH("Wizard",'Spells List'!$D36)),'Spells List'!D36,"") -> Wizard | E19: =IF(ISNUMBER(SEARCH("Wizard",'Spells List'!$D36)),'Spells List'!E36,"") -> Focus | F19: =IF(ISNUMBER(SEARCH("Wizard",'Spells List'!$D36)),'Spells List'!F36,"") -> Near | G19: =IF(ISNUMBER(SEARCH("Wizard",'Spells List'!$D36)),'Spells List'!G36,"") -> You magically paralyze one humanoid creature of LV 4 or less you can see within range.
A20: =IF(ISNUMBER(SEARCH("Wizard",'Spells List'!$D40)),'Spells List'!A40,"") -> CR | B20: =IF(ISNUMBER(SEARCH("Wizard",'Spells List'!$D40)),'Spells List'!B40,"") -> Invisibility | C20: =IF(ISNUMBER(SEARCH("Wizard",'Spells List'!$D40)),'Spells List'!C40,"") -> 2 | D20: =IF(ISNUMBER(SEARCH("Wizard",'Spells List'!$D40)),'Spells List'!D40,"") -> Wizard | E20: =IF(ISNUMBER(SEARCH("Wizard",'Spells List'!$D40)),'Spells List'!E40,"") -> 10 rounds | F20: =IF(ISNUMBER(SEARCH("Wizard",'Spells List'!$D40)),'Spells List'!F40,"") -> Close | G20: =IF(ISNUMBER(SEARCH("Wizard",'Spells List'!$D40)),'Spells List'!G40,"") -> A creature you touch becomes invisible for the spell’s duration. The spell ends if the target attacks or casts a spell.
A21: =IF(ISNUMBER(SEARCH("Wizard",'Spells List'!$D42)),'Spells List'!A42,"") -> CR | B21: =IF(ISNUMBER(SEARCH("Wizard",'Spells List'!$D42)),'Spells List'!B42,"") -> Knock | C21: =IF(ISNUMBER(SEARCH("Wizard",'Spells List'!$D42)),'Spells List'!C42,"") -> 2 | D21: =IF(ISNUMBER(SEARCH("Wizard",'Spells List'!$D42)),'Spells List'!D42,"") -> Wizard | E21: =IF(ISNUMBER(SEARCH("Wizard",'Spells List'!$D42)),'Spells List'!E42,"") -> Instant | F21: =IF(ISNUMBER(SEARCH("Wizard",'Spells List'!$D42)),'Spells List'!F42,"") -> Near | G21: =IF(ISNUMBER(SEARCH("Wizard",'Spells List'!$D42)),'Spells List'!G42,"") -> A door, window, gate, chest, or portal you can see within range instantly opens, defeating all mundane locks and barriers. This spell creates a loud knock audible to all within earshot.
A22: =IF(ISNUMBER(SEARCH("Wizard",'Spells List'!$D44)),'Spells List'!A44,"") -> CR | B22: =IF(ISNUMBER(SEARCH("Wizard",'Spells List'!$D44)),'Spells List'!B44,"") -> Levitate | C22: =IF(ISNUMBER(SEARCH("Wizard",'Spells List'!$D44)),'Spells List'!C44,"") -> 2 | D22: =IF(ISNUMBER(SEARCH("Wizard",'Spells List'!$D44)),'Spells List'!D44,"") -> Wizard | E22: =IF(ISNUMBER(SEARCH("Wizard",'Spells List'!$D44)),'Spells List'!E44,"") -> Focus | F22: =IF(ISNUMBER(SEARCH("Wizard",'Spells List'!$D44)),'Spells List'!F44,"") -> Self | G22: =IF(ISNUMBER(SEARCH("Wizard",'Spells List'!$D44)),'Spells List'!G44,"") -> You can float a near distance vertically per round on your turn. You can also push against solid objects to move horizontally.
A23: =IF(ISNUMBER(SEARCH("Wizard",'Spells List'!$D51)),'Spells List'!A51,"") -> CR | B23: =IF(ISNUMBER(SEARCH("Wizard",'Spells List'!$D51)),'Spells List'!B51,"") -> Mirror Image | C23: =IF(ISNUMBER(SEARCH("Wizard",'Spells List'!$D51)),'Spells List'!C51,"") -> 2 | D23: =IF(ISNUMBER(SEARCH("Wizard",'Spells List'!$D51)),'Spells List'!D51,"") -> Wizard | E23: =IF(ISNUMBER(SEARCH("Wizard",'Spells List'!$D51)),'Spells List'!E51,"") -> 5 rounds | F23: =IF(ISNUMBER(SEARCH("Wizard",'Spells List'!$D51)),'Spells List'!F51,"") -> Self | G23: =IF(ISNUMBER(SEARCH("Wizard",'Spells List'!$D51)),'Spells List'!G51,"") -> Create a number of illusory duplicates of yourself equal to half your level rounded down (minimum 1). Each time a creature attacks you, the attack misses and causes one of the duplicates to evaporate. If all the illusions have disappeared, the spell ends.
A24: =IF(ISNUMBER(SEARCH("Wizard",'Spells List'!$D52)),'Spells List'!A52,"") -> CR | B24: =IF(ISNUMBER(SEARCH("Wizard",'Spells List'!$D52)),'Spells List'!B52,"") -> Misty Step | C24: =IF(ISNUMBER(SEARCH("Wizard",'Spells List'!$D52)),'Spells List'!C52,"") -> 2 | D24: =IF(ISNUMBER(SEARCH("Wizard",'Spells List'!$D52)),'Spells List'!D52,"") -> Wizard | E24: =IF(ISNUMBER(SEARCH("Wizard",'Spells List'!$D52)),'Spells List'!E52,"") -> Instant | F24: =IF(ISNUMBER(SEARCH("Wizard",'Spells List'!$D52)),'Spells List'!F52,"") -> Self | G24: =IF(ISNUMBER(SEARCH("Wizard",'Spells List'!$D52)),'Spells List'!G52,"") -> In a puff of smoke, you teleport a near distance to an area you can see.
A25: =IF(ISNUMBER(SEARCH("Wizard",'Spells List'!$D67)),'Spells List'!A67,"") -> CR | B25: =IF(ISNUMBER(SEARCH("Wizard",'Spells List'!$D67)),'Spells List'!B67,"") -> Silence | C25: =IF(ISNUMBER(SEARCH("Wizard",'Spells List'!$D67)),'Spells List'!C67,"") -> 2 | D25: =IF(ISNUMBER(SEARCH("Wizard",'Spells List'!$D67)),'Spells List'!D67,"") -> Wizard | E25: =IF(ISNUMBER(SEARCH("Wizard",'Spells List'!$D67)),'Spells List'!E67,"") -> Focus | F25: =IF(ISNUMBER(SEARCH("Wizard",'Spells List'!$D67)),'Spells List'!F67,"") -> Far | G25: =IF(ISNUMBER(SEARCH("Wizard",'Spells List'!$D67)),'Spells List'!G67,"") -> You magically mute sound in a near cube within the spell’s range. Creatures inside the area are deafened, and any sounds they create cannot be heard.
A26: =IF(ISNUMBER(SEARCH("Wizard",'Spells List'!$D76)),'Spells List'!A76,"") -> CR | B26: =IF(ISNUMBER(SEARCH("Wizard",'Spells List'!$D76)),'Spells List'!B76,"") -> Web | C26: =IF(ISNUMBER(SEARCH("Wizard",'Spells List'!$D76)),'Spells List'!C76,"") -> 2 | D26: =IF(ISNUMBER(SEARCH("Wizard",'Spells List'!$D76)),'Spells List'!D76,"") -> Wizard | E26: =IF(ISNUMBER(SEARCH("Wizard",'Spells List'!$D76)),'Spells List'!E76,"") -> 5 rounds | F26: =IF(ISNUMBER(SEARCH("Wizard",'Spells List'!$D76)),'Spells List'!F76,"") -> Far | G26: =IF(ISNUMBER(SEARCH("Wizard",'Spells List'!$D76)),'Spells List'!G76,"") -> Creates a near-sized cube of sticky spider web within range. Creatures stuck in the web must succeed on a Strength check vs. your spellcasting check to free themselves.
A27: =IF(ISNUMBER(SEARCH("Wizard",'Spells List'!$D80)),'Spells List'!A80,"") -> CR | B27: =IF(ISNUMBER(SEARCH("Wizard",'Spells List'!$D80)),'Spells List'!B80,"") -> Alter Self | C27: =IF(ISNUMBER(SEARCH("Wizard",'Spells List'!$D80)),'Spells List'!C80,"") -> 2 | D27: =IF(ISNUMBER(SEARCH("Wizard",'Spells List'!$D80)),'Spells List'!D80,"") -> Wizard | E27: =IF(ISNUMBER(SEARCH("Wizard",'Spells List'!$D80)),'Spells List'!E80,"") -> 5 rounds | F27: =IF(ISNUMBER(SEARCH("Wizard",'Spells List'!$D80)),'Spells List'!F80,"") -> Self | G27: =IF(ISNUMBER(SEARCH("Wizard",'Spells List'!$D80)),'Spells List'!G80,"") -> You magically change your physical form, gaining one feature that modifies your existing anatomy. For example, you can grow functional gills on your neck or bear claws on your fingers. This spell can’t grow wings or limbs.
A28: =IF(ISNUMBER(SEARCH("Wizard",'Spells List'!$D6)),'Spells List'!A6,"") -> CR | B28: =IF(ISNUMBER(SEARCH("Wizard",'Spells List'!$D6)),'Spells List'!B6,"") -> Animate Dead | C28: =IF(ISNUMBER(SEARCH("Wizard",'Spells List'!$D6)),'Spells List'!C6,"") -> 3 | D28: =IF(ISNUMBER(SEARCH("Wizard",'Spells List'!$D6)),'Spells List'!D6,"") -> Wizard | E28: =IF(ISNUMBER(SEARCH("Wizard",'Spells List'!$D6)),'Spells List'!E6,"") -> 1 day | F28: =IF(ISNUMBER(SEARCH("Wizard",'Spells List'!$D6)),'Spells List'!F6,"") -> Close | G28: =IF(ISNUMBER(SEARCH("Wizard",'Spells List'!$D6)),'Spells List'!G6,"") -> You touch one humanoid’s remains, and it rises as a zombie or skeleton under your control. The remains must have at least three limbs and its head intact. The undead creature acts on your turn. After 1 day, the creature collapses into grave dust.
A29: =IF(ISNUMBER(SEARCH("Wizard",'Spells List'!$D23)),'Spells List'!A23,"") -> CR | B29: =IF(ISNUMBER(SEARCH("Wizard",'Spells List'!$D23)),'Spells List'!B23,"") -> Dispel Magic | C29: =IF(ISNUMBER(SEARCH("Wizard",'Spells List'!$D23)),'Spells List'!C23,"") -> 3 | D29: =IF(ISNUMBER(SEARCH("Wizard",'Spells List'!$D23)),'Spells List'!D23,"") -> Wizard | E29: =IF(ISNUMBER(SEARCH("Wizard",'Spells List'!$D23)),'Spells List'!E23,"") -> Instant | F29: =IF(ISNUMBER(SEARCH("Wizard",'Spells List'!$D23)),'Spells List'!F23,"") -> Near | G29: =IF(ISNUMBER(SEARCH("Wizard",'Spells List'!$D23)),'Spells List'!G23,"") -> End one spell that affects one target you can see in range.
A30: =IF(ISNUMBER(SEARCH("Wizard",'Spells List'!$D26)),'Spells List'!A26,"") -> CR | B30: =IF(ISNUMBER(SEARCH("Wizard",'Spells List'!$D26)),'Spells List'!B26,"") -> Fabricate | C30: =IF(ISNUMBER(SEARCH("Wizard",'Spells List'!$D26)),'Spells List'!C26,"") -> 3 | D30: =IF(ISNUMBER(SEARCH("Wizard",'Spells List'!$D26)),'Spells List'!D26,"") -> Wizard | E30: =IF(ISNUMBER(SEARCH("Wizard",'Spells List'!$D26)),'Spells List'!E26,"") -> 10 rounds | F30: =IF(ISNUMBER(SEARCH("Wizard",'Spells List'!$D26)),'Spells List'!F26,"") -> Near | G30: =IF(ISNUMBER(SEARCH("Wizard",'Spells List'!$D26)),'Spells List'!G26,"") -> This spell can't target creatures. You turn a tree-sized collection of raw materials into a finished work. For example, you convert a pile of bricks or rocks into a bridge. The finished work converts back to raw materials when the spell ends.
A31: =IF(ISNUMBER(SEARCH("Wizard",'Spells List'!$D28)),'Spells List'!A28,"") -> CR | B31: =IF(ISNUMBER(SEARCH("Wizard",'Spells List'!$D28)),'Spells List'!B28,"") -> Fireball | C31: =IF(ISNUMBER(SEARCH("Wizard",'Spells List'!$D28)),'Spells List'!C28,"") -> 3 | D31: =IF(ISNUMBER(SEARCH("Wizard",'Spells List'!$D28)),'Spells List'!D28,"") -> Wizard | E31: =IF(ISNUMBER(SEARCH("Wizard",'Spells List'!$D28)),'Spells List'!E28,"") -> Instant | F31: =IF(ISNUMBER(SEARCH("Wizard",'Spells List'!$D28)),'Spells List'!F28,"") -> Far | G31: =IF(ISNUMBER(SEARCH("Wizard",'Spells List'!$D28)),'Spells List'!G28,"") -> You hurl a small flame that erupts into a fiery blast. All creatures in a near-sized cube around where the flame lands take 4d6 damage.
A32: =IF(ISNUMBER(SEARCH("Wizard",'Spells List'!$D32)),'Spells List'!A32,"") -> CR | B32: =IF(ISNUMBER(SEARCH("Wizard",'Spells List'!$D32)),'Spells List'!B32,"") -> Fly | C32: =IF(ISNUMBER(SEARCH("Wizard",'Spells List'!$D32)),'Spells List'!C32,"") -> 3 | D32: =IF(ISNUMBER(SEARCH("Wizard",'Spells List'!$D32)),'Spells List'!D32,"") -> Wizard | E32: =IF(ISNUMBER(SEARCH("Wizard",'Spells List'!$D32)),'Spells List'!E32,"") -> 5 rounds | F32: =IF(ISNUMBER(SEARCH("Wizard",'Spells List'!$D32)),'Spells List'!F32,"") -> Self | G32: =IF(ISNUMBER(SEARCH("Wizard",'Spells List'!$D32)),'Spells List'!G32,"") -> Your feet lift from the ground, and you take to the air like a hummingbird. You can fly near for the spell's duration and are able to hover in place.
A33: =IF(ISNUMBER(SEARCH("Wizard",'Spells List'!$D33)),'Spells List'!A33,"") -> CR | B33: =IF(ISNUMBER(SEARCH("Wizard",'Spells List'!$D33)),'Spells List'!B33,"") -> Gaseous Form | C33: =IF(ISNUMBER(SEARCH("Wizard",'Spells List'!$D33)),'Spells List'!C33,"") -> 3 | D33: =IF(ISNUMBER(SEARCH("Wizard",'Spells List'!$D33)),'Spells List'!D33,"") -> Wizard | E33: =IF(ISNUMBER(SEARCH("Wizard",'Spells List'!$D33)),'Spells List'!E33,"") -> 10 rounds | F33: =IF(ISNUMBER(SEARCH("Wizard",'Spells List'!$D33)),'Spells List'!F33,"") -> Self | G33: =IF(ISNUMBER(SEARCH("Wizard",'Spells List'!$D33)),'Spells List'!G33,"") -> You and your gear turn into a cloud of smoke for the spell's duration. You can fly and pass through any gap that smoke could. You can sense the terrain and any movement around you out to a near distance. You can't cast spells while in this form.
A34: =IF(ISNUMBER(SEARCH("Wizard",'Spells List'!$D39)),'Spells List'!A39,"") -> CR | B34: =IF(ISNUMBER(SEARCH("Wizard",'Spells List'!$D39)),'Spells List'!B39,"") -> Illusion | C34: =IF(ISNUMBER(SEARCH("Wizard",'Spells List'!$D39)),'Spells List'!C39,"") -> 3 | D34: =IF(ISNUMBER(SEARCH("Wizard",'Spells List'!$D39)),'Spells List'!D39,"") -> Wizard | E34: =IF(ISNUMBER(SEARCH("Wizard",'Spells List'!$D39)),'Spells List'!E39,"") -> Focus | F34: =IF(ISNUMBER(SEARCH("Wizard",'Spells List'!$D39)),'Spells List'!F39,"") -> Far | G34: =IF(ISNUMBER(SEARCH("Wizard",'Spells List'!$D39)),'Spells List'!G39,"") -> You create a convincing visible and audible illusion that fills up to a near-sized cube in range. The illusion cannot cause harm, but creatures who believe the illusion is real react to it as though it were. A creature who inspects the illusion from afar must pass a Wisdom check vs. your last spellcasting check to perceive the false nature of the illusion. Touching the illusion also reveals its false nature.
A35: =IF(ISNUMBER(SEARCH("Wizard",'Spells List'!$D46)),'Spells List'!A46,"") -> CR | B35: =IF(ISNUMBER(SEARCH("Wizard",'Spells List'!$D46)),'Spells List'!B46,"") -> Lightning Bolt | C35: =IF(ISNUMBER(SEARCH("Wizard",'Spells List'!$D46)),'Spells List'!C46,"") -> 3 | D35: =IF(ISNUMBER(SEARCH("Wizard",'Spells List'!$D46)),'Spells List'!D46,"") -> Wizard | E35: =IF(ISNUMBER(SEARCH("Wizard",'Spells List'!$D46)),'Spells List'!E46,"") -> Instant | F35: =IF(ISNUMBER(SEARCH("Wizard",'Spells List'!$D46)),'Spells List'!F46,"") -> Far | G35: =IF(ISNUMBER(SEARCH("Wizard",'Spells List'!$D46)),'Spells List'!G46,"") -> You shoot a blue-white ray of lightning from your hands, hitting all creatures in a straight line out to a far distance. Creatures struck by the lightning take 3d6 damage.
A36: =IF(ISNUMBER(SEARCH("Wizard",'Spells List'!$D48)),'Spells List'!A48,"") -> CR | B36: =IF(ISNUMBER(SEARCH("Wizard",'Spells List'!$D48)),'Spells List'!B48,"") -> Magic Circle | C36: =IF(ISNUMBER(SEARCH("Wizard",'Spells List'!$D48)),'Spells List'!C48,"") -> 3 | D36: =IF(ISNUMBER(SEARCH("Wizard",'Spells List'!$D48)),'Spells List'!D48,"") -> Wizard | E36: =IF(ISNUMBER(SEARCH("Wizard",'Spells List'!$D48)),'Spells List'!E48,"") -> Focus | F36: =IF(ISNUMBER(SEARCH("Wizard",'Spells List'!$D48)),'Spells List'!F48,"") -> Near | G36: =IF(ISNUMBER(SEARCH("Wizard",'Spells List'!$D48)),'Spells List'!G48,"") -> Conjure a circle of runes around yourself and name a type of creature. Creatures of the chosen type cannot attack or cast hostile spells on anyone inside the circle, and can't possess, compel, or beguile anyone inside the circle.
A37: =IF(ISNUMBER(SEARCH("Wizard",'Spells List'!$D59)),'Spells List'!A59,"") -> CR | B37: =IF(ISNUMBER(SEARCH("Wizard",'Spells List'!$D59)),'Spells List'!B59,"") -> Protection From Energy | C37: =IF(ISNUMBER(SEARCH("Wizard",'Spells List'!$D59)),'Spells List'!C59,"") -> 3 | D37: =IF(ISNUMBER(SEARCH("Wizard",'Spells List'!$D59)),'Spells List'!D59,"") -> Wizard | E37: =IF(ISNUMBER(SEARCH("Wizard",'Spells List'!$D59)),'Spells List'!E59,"") -> 10 minutes | F37: =IF(ISNUMBER(SEARCH("Wizard",'Spells List'!$D59)),'Spells List'!F59,"") -> Close | G37: =IF(ISNUMBER(SEARCH("Wizard",'Spells List'!$D59)),'Spells List'!G59,"") -> One creature you touch becomes impervious to the wild fury of the elements. Choose fire, cold, or electricity. For the spell's duration, the target is immune to harm from energy of the chosen type.
A38: =IF(ISNUMBER(SEARCH("Wizard",'Spells List'!$D65)),'Spells List'!A65,"") -> CR | B38: =IF(ISNUMBER(SEARCH("Wizard",'Spells List'!$D65)),'Spells List'!B65,"") -> Sending | C38: =IF(ISNUMBER(SEARCH("Wizard",'Spells List'!$D65)),'Spells List'!C65,"") -> 3 | D38: =IF(ISNUMBER(SEARCH("Wizard",'Spells List'!$D65)),'Spells List'!D65,"") -> Wizard | E38: =IF(ISNUMBER(SEARCH("Wizard",'Spells List'!$D65)),'Spells List'!E65,"") -> Instant | F38: =IF(ISNUMBER(SEARCH("Wizard",'Spells List'!$D65)),'Spells List'!F65,"") -> Unlimited | G38: =IF(ISNUMBER(SEARCH("Wizard",'Spells List'!$D65)),'Spells List'!G65,"") -> You send a brief, mental message to any creature with whom you are familiar who is on the same plane.
